<?xml version="1.0" encoding="utf-8"?>
<!-- This URDF was automatically created by SolidWorks to URDF Exporter! Originally created by Stephen Brawner (brawner@gmail.com) 
     Commit Version: 1.5.0-0-g9aa0fdb  Build Version: 1.5.7004.21443
     For more information, please see http://wiki.ros.org/sw_urdf_exporter -->
<robot
  name="mutifingerhand">
  <link
    name="Plam">
<!--    <inertial>
      <origin
        xyz="-0.0258585624172266 -0.0447883427186679 -0.00792482655775652"
        rpy="0 0 0" />
      <mass
        value="1.74090727868219" />
      <inertia
        ixx="0.0177421238548285"
        ixy="-0.00221485071583829"
        ixz="0.000357467149758205"
        iyy="0.0151846344467882"
        iyz="0.000619151483781683"
        izz="0.00547612023214745" />
    </inertial>-->
    <visual>
      <origin
        xyz="0 0 0"
        rpy="0 0 0" />
      <geometry>
        <mesh
          filename="package://mutifingerhand_qi_urdf/meshes/Plam.STL" />
      </geometry>
      <material
        name="">
        <color
          rgba="0.298039215686275 0.298039215686275 0.298039215686275 1" />
      </material>
    </visual>
    <collision>
      <origin
        xyz="0 0 0"
        rpy="0 0 0" />
      <geometry>
        <mesh
          filename="package://mutifingerhand_qi_urdf/meshes/Plam.STL" />
      </geometry>
    </collision>
  </link>
  <link
    name="L11">
    <inertial>
      <origin
        xyz="0.0456151825139556 -1.38777878078145E-17 -0.0269148979358349"
        rpy="0 0 0" />
      <mass
        value="0.025498450699204" />
      <inertia
        ixx="3.40990718417786E-06"
        ixy="-1.48230765769503E-21"
        ixz="-2.77198628957502E-06"
        iyy="1.78536582358482E-05"
        iyz="-4.6500911586765E-22"
        izz="1.85524834440482E-05" />
    </inertial>
    <visual>
      <origin
        xyz="0 0 0"
        rpy="0 0 0" />
      <geometry>
        <mesh
          filename="package://mutifingerhand_qi_urdf/meshes/L11.STL" />
      </geometry>
      <material
        name="">
        <color
          rgba="0.968627450980392 0.258823529411765 0.258823529411765 1" />
      </material>
    </visual>
    <collision>
      <origin
        xyz="0 0 0"
        rpy="0 0 0" />
      <geometry>
        <mesh
          filename="package://mutifingerhand_qi_urdf/meshes/L11.STL" />
      </geometry>
    </collision>
  </link>
  <joint
    name="J11"
    type="revolute">
    <origin
      xyz="0 0 0"
      rpy="0 0 0" />
    <parent
      link="Plam" />
    <child
      link="L11" />
    <axis
      xyz="0 0 1" />
    <limit
      lower="-1.5"
      upper="0.4"
      effort="10"
      velocity="0.2" />
    <safety_controller
      k_velocity="0.2"
      k_position="3"
      soft_lower_limit = "-1.5"
      soft_upper_limit = "0.4"/>
  </joint>
  <link
    name="L12">
    <inertial>
      <origin
        xyz="2.77555756156289E-17 1.45464950654373E-07 1.45464950654373E-07"
        rpy="0 0 0" />
      <mass
        value="0.00533032952331042" />
      <inertia
        ixx="3.90144153680474E-07"
        ixy="1.02097316129139E-11"
        ixz="-1.02097316129135E-11"
        iyy="4.31614139914132E-07"
        iyz="1.12789954344317E-16"
        izz="4.31614139914132E-07" />
    </inertial>
    <visual>
      <origin
        xyz="0 0 0"
        rpy="0 0 0" />
      <geometry>
        <mesh
          filename="package://mutifingerhand_qi_urdf/meshes/L12.STL" />
      </geometry>
      <material
        name="">
        <color
          rgba="0.647058823529412 0.619607843137255 0.588235294117647 1" />
      </material>
    </visual>
    <collision>
      <origin
        xyz="0 0 0"
        rpy="0 0 0" />
      <geometry>
        <mesh
          filename="package://mutifingerhand_qi_urdf/meshes/L12.STL" />
      </geometry>
    </collision>
  </link>
  <joint
    name="J12"
    type="revolute">
    <origin
      xyz="0.07 0 0"
      rpy="1.5707963267949 -1.5707963267949 0" />
    <parent
      link="L11" />
    <child
      link="L12" />
    <axis
      xyz="0 0 1" />
    <limit
    lower="0"
    upper="1.5707963267949"
    effort="10"
    velocity="0.2" />
    <safety_controller
    k_velocity="0.2"
    k_position="3"
    soft_lower_limit = "0"
    soft_upper_limit = "1.5707963267949"/>
  </joint>
  <link
    name="L13">
    <inertial>
      <origin
        xyz="0.025739 -5.5511E-17 0"
        rpy="0 0 0" />
      <mass
        value="0.021339" />
      <inertia
        ixx="3.1394E-06"
        ixy="-6.7982E-23"
        ixz="-2.3507E-22"
        iyy="3.2439E-06"
        iyz="8.4703E-22"
        izz="3.3284E-06" />
    </inertial>
    <visual>
      <origin
        xyz="0 0 0"
        rpy="0 0 0" />
      <geometry>
        <mesh
          filename="package://mutifingerhand_qi_urdf/meshes/L13.STL" />
      </geometry>
      <material
        name="">
        <color
          rgba="1 1 1 1" />
      </material>
    </visual>
    <collision>
      <origin
        xyz="0 0 0"
        rpy="0 0 0" />
      <geometry>
        <mesh
          filename="package://mutifingerhand_qi_urdf/meshes/L13.STL" />
      </geometry>
    </collision>
  </link>
  <joint
    name="J13"
    type="revolute">
    <origin
      xyz="0 0 0"
      rpy="-1.5708 0 0" />
    <parent
      link="L12" />
    <child
      link="L13" />
    <axis
      xyz="0 0 1" />
    <limit
    lower="-0.34906585039"
    upper="0.34906585039"
    effort="10"
    velocity="0.2" />
    <safety_controller
    k_velocity="0.2"
    k_position="3"
    soft_lower_limit = "-0.34906585039"
    soft_upper_limit = "0.34906585039"/>
  </joint>
  <link
    name="L14">
    <inertial>
      <origin
        xyz="0.03 1.38777878078145E-17 1.38777878078145E-17"
        rpy="0 0 0" />
      <mass
        value="0.0432977871437822" />
      <inertia
        ixx="6.10360523604235E-06"
        ixy="3.40544233741442E-22"
        ixz="-2.68196390977369E-21"
        iyy="1.24187338524514E-05"
        iyz="1.27054942088145E-21"
        izz="1.27607093027641E-05" />
    </inertial>
    <visual>
      <origin
        xyz="0 0 0"
        rpy="0 0 0" />
      <geometry>
        <mesh
          filename="package://mutifingerhand_qi_urdf/meshes/L14.STL" />
      </geometry>
      <material
        name="">
        <color
          rgba="0.650980392156863 0.619607843137255 0.588235294117647 1" />
      </material>
    </visual>
    <collision>
      <origin
        xyz="0 0 0"
        rpy="0 0 0" />
      <geometry>
        <mesh
          filename="package://mutifingerhand_qi_urdf/meshes/L14.STL" />
      </geometry>
    </collision>
  </link>
  <joint
    name="J14"
    type="revolute">
    <origin
      xyz="0.05 0 0"
      rpy="1.5707963267949 0 0" />
    <parent
      link="L13" />
    <child
      link="L14" />
    <axis
      xyz="0 0 1" />
    <limit
    lower="0"
    upper="1.5707963267949"
    effort="10"
    velocity="0.2" />
    <safety_controller
    k_velocity="0.2"
    k_position="3"
    soft_lower_limit = "0"
    soft_upper_limit = "1.5707963267949"/>
  </joint>
  <link
    name="L15">
    <inertial>
      <origin
        xyz="0.0294288024878977 1.38777878078145E-17 0"
        rpy="0 0 0" />
      <mass
        value="0.0306024106567816" />
      <inertia
        ixx="4.30360645164556E-06"
        ixy="-1.49716591271013E-21"
        ixz="-1.02371615035018E-21"
        iyy="6.12985569320618E-06"
        iyz="0"
        izz="5.6497981829401E-06" />
    </inertial>
    <visual>
      <origin
        xyz="0 0 0"
        rpy="0 0 0" />
      <geometry>
        <mesh
          filename="package://mutifingerhand_qi_urdf/meshes/L15.STL" />
      </geometry>
      <material
        name="">
        <color
          rgba="1 1 1 1" />
      </material>
    </visual>
    <collision>
      <origin
        xyz="0 0 0"
        rpy="0 0 0" />
      <geometry>
        <mesh
          filename="package://mutifingerhand_qi_urdf/meshes/L15.STL" />
      </geometry>
    </collision>
  </link>
  <joint
    name="J15"
    type="revolute">
    <origin
      xyz="0.06 0 0"
      rpy="0 0 0" />
    <parent
      link="L14" />
    <child
      link="L15" />
    <axis
      xyz="0 0 1" />
    <limit
    lower="0"
    upper="1.5707963267949"
    effort="10"
    velocity="0.2" />
    <safety_controller
    k_velocity="0.2"
    k_position="3"
    soft_lower_limit = "0"
    soft_upper_limit = "1.5707963267949"/>
  </joint>
  <link
    name="L21">
    <inertial>
      <origin
        xyz="-6.93889390390723E-18 -1.4546495064223E-07 -1.45464950647434E-07"
        rpy="0 0 0" />
      <mass
        value="0.00533032952331042" />
      <inertia
        ixx="3.90144153680474E-07"
        ixy="-1.02097316130172E-11"
        ixz="1.02097316129302E-11"
        iyy="4.31614139914132E-07"
        iyz="1.12790059481656E-16"
        izz="4.31614139914132E-07" />
    </inertial>
    <visual>
      <origin
        xyz="0 0 0"
        rpy="0 0 0" />
      <geometry>
        <mesh
          filename="package://mutifingerhand_qi_urdf/meshes/L21.STL" />
      </geometry>
      <material
        name="">
        <color
          rgba="0.647058823529412 0.619607843137255 0.588235294117647 1" />
      </material>
    </visual>
    <collision>
      <origin
        xyz="0 0 0"
        rpy="0 0 0" />
      <geometry>
        <mesh
          filename="package://mutifingerhand_qi_urdf/meshes/L21.STL" />
      </geometry>
    </collision>
  </link>
  <joint
    name="J21"
    type="revolute">
    <origin
      xyz="-0.0122172386608746 -0.0211608780888301 0.16"
      rpy="1.04719755119661 -1.5707963267949 0" />
    <parent
      link="Plam" />
    <child
      link="L21" />
    <axis
      xyz="0 0 -1" />
    <limit
    lower="0"
    upper="1.5707963267949"
    effort="10"
    velocity="0.2" />
    <safety_controller
    k_velocity="0.2"
    k_position="3"
    soft_lower_limit = "0"
    soft_upper_limit = "1.5707963267949"/>
  </joint>
  <link
    name="L22">
    <inertial>
      <origin
        xyz="0.0257389350848426 0 3.46944695195361E-18"
        rpy="0 0 0" />
      <mass
        value="0.021339303176374" />
      <inertia
        ixx="3.13943117425313E-06"
        ixy="2.54748214715417E-22"
        ixz="-2.78389030314293E-22"
        iyy="3.24390776504185E-06"
        iyz="-2.73034225627855E-22"
        izz="3.328353678847E-06" />
    </inertial>
    <visual>
      <origin
        xyz="0 0 0"
        rpy="0 0 0" />
      <geometry>
        <mesh
          filename="package://mutifingerhand_qi_urdf/meshes/L22.STL" />
      </geometry>
      <material
        name="">
        <color
          rgba="1 1 1 1" />
      </material>
    </visual>
    <collision>
      <origin
        xyz="0 0 0"
        rpy="0 0 0" />
      <geometry>
        <mesh
          filename="package://mutifingerhand_qi_urdf/meshes/L22.STL" />
      </geometry>
    </collision>
  </link>
  <joint
    name="J22"
    type="revolute">
    <origin
      xyz="0 0 0"
      rpy="-1.5707963267949 0 0" />
    <parent
      link="L21" />
    <child
      link="L22" />
    <axis
      xyz="0 0 -1" />
    <limit
    lower="-0.34906585039"
    upper="0.34906585039"
    effort="10"
    velocity="0.2" />
    <safety_controller
    k_velocity="0.2"
    k_position="3"
    soft_lower_limit = "-0.34906585039"
    soft_upper_limit = "0.34906585039"/>
  </joint>
  <link
    name="L23">
    <inertial>
      <origin
        xyz="0.03 3.46944695195361E-18 5.55111512312578E-17"
        rpy="0 0 0" />
      <mass
        value="0.0432977871437822" />
      <inertia
        ixx="6.10360523604235E-06"
        ixy="1.27609365295756E-22"
        ixz="-4.34709229312595E-21"
        iyy="1.24187338524514E-05"
        iyz="-2.81813461298772E-22"
        izz="1.27607093027641E-05" />
    </inertial>
    <visual>
      <origin
        xyz="0 0 0"
        rpy="0 0 0" />
      <geometry>
        <mesh
          filename="package://mutifingerhand_qi_urdf/meshes/L23.STL" />
      </geometry>
      <material
        name="">
        <color
          rgba="0.650980392156863 0.619607843137255 0.588235294117647 1" />
      </material>
    </visual>
    <collision>
      <origin
        xyz="0 0 0"
        rpy="0 0 0" />
      <geometry>
        <mesh
          filename="package://mutifingerhand_qi_urdf/meshes/L23.STL" />
      </geometry>
    </collision>
  </link>
  <joint
    name="J23"
    type="revolute">
    <origin
      xyz="0.05 0 0"
      rpy="1.5707963267949 0 0" />
    <parent
      link="L22" />
    <child
      link="L23" />
    <axis
      xyz="0 0 -1" />
    <limit
    lower="0"
    upper="1.5707963267949"
    effort="10"
    velocity="0.2" />
    <safety_controller
    k_velocity="0.2"
    k_position="3"
    soft_lower_limit = "0"
    soft_upper_limit = "1.5707963267949"/>
  </joint>
  <link
    name="L24">
    <inertial>
      <origin
        xyz="0.0294288024878977 -2.94902990916057E-17 1.11022302462516E-16"
        rpy="0 0 0" />
      <mass
        value="0.0306024106567816" />
      <inertia
        ixx="4.30360645164556E-06"
        ixy="1.18797029495754E-21"
        ixz="-4.46855167141231E-22"
        iyy="6.12985569320617E-06"
        iyz="1.80427544210057E-22"
        izz="5.6497981829401E-06" />
    </inertial>
    <visual>
      <origin
        xyz="0 0 0"
        rpy="0 0 0" />
      <geometry>
        <mesh
          filename="package://mutifingerhand_qi_urdf/meshes/L24.STL" />
      </geometry>
      <material
        name="">
        <color
          rgba="1 1 1 1" />
      </material>
    </visual>
    <collision>
      <origin
        xyz="0 0 0"
        rpy="0 0 0" />
      <geometry>
        <mesh
          filename="package://mutifingerhand_qi_urdf/meshes/L24.STL" />
      </geometry>
    </collision>
  </link>
  <joint
    name="J24"
    type="revolute">
    <origin
      xyz="0.06 0 0"
      rpy="0 0 0" />
    <parent
      link="L23" />
    <child
      link="L24" />
    <axis
      xyz="0 0 -1" />
    <limit
    lower="0"
    upper="1.5707963267949"
    effort="10"
    velocity="0.2" />
    <safety_controller
    k_velocity="0.2"
    k_position="3"
    soft_lower_limit = "0"
    soft_upper_limit = "1.5707963267949"/>
  </joint>
  <link
    name="L31">
    <inertial>
      <origin
        xyz="-6.93889390390723E-18 -1.45464950640495E-07 -1.45464950645699E-07"
        rpy="0 0 0" />
      <mass
        value="0.00533032952331042" />
      <inertia
        ixx="3.90144153680474E-07"
        ixy="-1.02097316129807E-11"
        ixz="1.02097316129821E-11"
        iyy="4.31614139914132E-07"
        iyz="1.12790032419864E-16"
        izz="4.31614139914132E-07" />
    </inertial>
    <visual>
      <origin
        xyz="0 0 0"
        rpy="0 0 0" />
      <geometry>
        <mesh
          filename="package://mutifingerhand_qi_urdf/meshes/L31.STL" />
      </geometry>
      <material
        name="">
        <color
          rgba="0.647058823529412 0.619607843137255 0.588235294117647 1" />
      </material>
    </visual>
    <collision>
      <origin
        xyz="0 0 0"
        rpy="0 0 0" />
      <geometry>
        <mesh
          filename="package://mutifingerhand_qi_urdf/meshes/L31.STL" />
      </geometry>
    </collision>
  </link>
  <joint
    name="J31"
    type="revolute">
    <origin
      xyz="-0.042217 -0.073122 0.16"
      rpy="1.0472 -1.5708 0" />
    <parent
      link="Plam" />
    <child
      link="L31" />
    <axis
      xyz="0 0 -1" />
    <limit
    lower="0"
    upper="1.5707963267949"
    effort="10"
    velocity="0.2" />
    <safety_controller
    k_velocity="0.2"
    k_position="3"
    soft_lower_limit = "0"
    soft_upper_limit = "1.5707963267949"/>
  </joint>
  <link
    name="L32">
    <inertial>
      <origin
        xyz="0.0257389063394541 -3.84675260140278E-05 3.46944695195361E-18"
        rpy="0 0 0" />
      <mass
        value="0.0213393031763741" />
      <inertia
        ixx="3.1394314076131E-06"
        ixy="1.56142881296529E-10"
        ixz="-1.45456208287766E-22"
        iyy="3.24390753168189E-06"
        iyz="1.00080490994555E-23"
        izz="3.32835367884701E-06" />
    </inertial>
    <visual>
      <origin
        xyz="0 0 0"
        rpy="0 0 0" />
      <geometry>
        <mesh
          filename="package://mutifingerhand_qi_urdf/meshes/L32.STL" />
      </geometry>
      <material
        name="">
        <color
          rgba="1 1 1 1" />
      </material>
    </visual>
    <collision>
      <origin
        xyz="0 0 0"
        rpy="0 0 0" />
      <geometry>
        <mesh
          filename="package://mutifingerhand_qi_urdf/meshes/L32.STL" />
      </geometry>
    </collision>
  </link>
  <joint
    name="J32"
    type="revolute">
    <origin
      xyz="0 0 0"
      rpy="-1.5708 0 0" />
    <parent
      link="L31" />
    <child
      link="L32" />
    <axis
      xyz="0 0 -1" />
    <limit
        lower="-0.34906585039"
        upper="0.34906585039"
        effort="10"
        velocity="0.2" />
    <safety_controller
        k_velocity="0.2"
        k_position="3"
        soft_lower_limit = "-0.34906585039"
        soft_upper_limit = "0.34906585039"/>
  </joint>
  <link
    name="L33">
    <inertial>
      <origin
        xyz="0.03 3.46944695195361E-18 1.73472347597681E-18"
        rpy="0 0 0" />
      <mass
        value="0.0432977871437822" />
      <inertia
        ixx="6.10360523604236E-06"
        ixy="2.82867588200968E-22"
        ixz="-7.23783035983899E-22"
        iyy="1.24187338524514E-05"
        iyz="1.11803738173056E-22"
        izz="1.27607093027641E-05" />
    </inertial>
    <visual>
      <origin
        xyz="0 0 0"
        rpy="0 0 0" />
      <geometry>
        <mesh
          filename="package://mutifingerhand_qi_urdf/meshes/L33.STL" />
      </geometry>
      <material
        name="">
        <color
          rgba="0.650980392156863 0.619607843137255 0.588235294117647 1" />
      </material>
    </visual>
    <collision>
      <origin
        xyz="0 0 0"
        rpy="0 0 0" />
      <geometry>
        <mesh
          filename="package://mutifingerhand_qi_urdf/meshes/L33.STL" />
      </geometry>
    </collision>
  </link>
  <joint
    name="J33"
    type="revolute">
    <origin
      xyz="0.05 -7.4726E-05 0"
      rpy="1.5708 0 -0.0014945" />
    <parent
      link="L32" />
    <child
      link="L33" />
    <axis
      xyz="0 0 -1" />
    <limit
        lower="0"
        upper="1.5707963267949"
        effort="10"
        velocity="0.2" />
    <safety_controller
        k_velocity="0.2"
        k_position="3"
        soft_lower_limit = "0"
        soft_upper_limit = "1.5707963267949"/>
  </joint>
  <link
    name="L34">
    <inertial>
      <origin
        xyz="0.0294288024878977 -2.42861286636753E-17 3.46944695195361E-18"
        rpy="0 0 0" />
      <mass
        value="0.0306024106567816" />
      <inertia
        ixx="4.30360645164556E-06"
        ixy="9.66613284042354E-22"
        ixz="6.95658895157096E-22"
        iyy="6.12985569320618E-06"
        iyz="-4.1075890436988E-22"
        izz="5.6497981829401E-06" />
    </inertial>
    <visual>
      <origin
        xyz="0 0 0"
        rpy="0 0 0" />
      <geometry>
        <mesh
          filename="package://mutifingerhand_qi_urdf/meshes/L34.STL" />
      </geometry>
      <material
        name="">
        <color
          rgba="1 1 1 1" />
      </material>
    </visual>
    <collision>
      <origin
        xyz="0 0 0"
        rpy="0 0 0" />
      <geometry>
        <mesh
          filename="package://mutifingerhand_qi_urdf/meshes/L34.STL" />
      </geometry>
    </collision>
  </link>
  <joint
    name="J34"
    type="revolute">
    <origin
      xyz="0.06 0 0"
      rpy="0 0 0" />
    <parent
      link="L33" />
    <child
      link="L34" />
    <axis
      xyz="0 0 -1" />
      <limit
        lower="0"
        upper="1.5707963267949"
        effort="10"
        velocity="0.2" />
      <safety_controller
        k_velocity="0.2"
        k_position="3"
        soft_lower_limit = "0"
        soft_upper_limit = "1.5707963267949"/>
  </joint>
  <link
    name="L41">
    <inertial>
      <origin
        xyz="6.93889390390723E-18 -1.45464950643964E-07 -1.45464950654373E-07"
        rpy="0 0 0" />
      <mass
        value="0.00533032952331043" />
      <inertia
        ixx="3.90144153680475E-07"
        ixy="-1.02097316129488E-11"
        ixz="1.02097316129707E-11"
        iyy="4.31614139914133E-07"
        iyz="1.12790036754609E-16"
        izz="4.31614139914133E-07" />
    </inertial>
    <visual>
      <origin
        xyz="0 0 0"
        rpy="0 0 0" />
      <geometry>
        <mesh
          filename="package://mutifingerhand_qi_urdf/meshes/L41.STL" />
      </geometry>
      <material
        name="">
        <color
          rgba="0.647058823529412 0.619607843137255 0.588235294117647 1" />
      </material>
    </visual>
    <collision>
      <origin
        xyz="0 0 0"
        rpy="0 0 0" />
      <geometry>
        <mesh
          filename="package://mutifingerhand_qi_urdf/meshes/L41.STL" />
      </geometry>
    </collision>
  </link>
  <joint
    name="J41"
    type="revolute">
    <origin
      xyz="-0.066029 -0.11437 0.13721"
      rpy="0 -0.87266 -2.0944" />
    <parent
      link="Plam" />
    <child
      link="L41" />
    <axis
      xyz="0 0 1" />
      <limit
        lower="0"
        upper="1.5707963267949"
        effort="10"
        velocity="0.2" />
      <safety_controller
        k_velocity="0.2"
        k_position="3"
        soft_lower_limit = "0"
        soft_upper_limit = "1.5707963267949"/>
  </joint>
  <link
    name="L42">
    <inertial>
      <origin
        xyz="0.0257389350848427 0 0"
        rpy="0 0 0" />
      <mass
        value="0.021339303176374" />
      <inertia
        ixx="3.13943117425313E-06"
        ixy="7.41153828847513E-22"
        ixz="-4.85733635652283E-22"
        iyy="3.24390776504185E-06"
        iyz="-3.46445106391177E-22"
        izz="3.328353678847E-06" />
    </inertial>
    <visual>
      <origin
        xyz="0 0 0"
        rpy="0 0 0" />
      <geometry>
        <mesh
          filename="package://mutifingerhand_qi_urdf/meshes/L42.STL" />
      </geometry>
      <material
        name="">
        <color
          rgba="1 1 1 1" />
      </material>
    </visual>
    <collision>
      <origin
        xyz="0 0 0"
        rpy="0 0 0" />
      <geometry>
        <mesh
          filename="package://mutifingerhand_qi_urdf/meshes/L42.STL" />
      </geometry>
    </collision>
  </link>
  <joint
    name="J42"
    type="revolute">
    <origin
      xyz="0 0 0"
      rpy="-1.5707963267949 0 0" />
    <parent
      link="L41" />
    <child
      link="L42" />
    <axis
      xyz="0 0 1" />
      <limit
        lower="-0.34906585039"
        upper="0.34906585039"
        effort="10"
        velocity="0.2" />
      <safety_controller
        k_velocity="0.2"
        k_position="3"
        soft_lower_limit = "-0.34906585039"
        soft_upper_limit = "0.34906585039"/>
  </joint>
  <link
    name="L43">
    <inertial>
      <origin
        xyz="0.03 3.46944695195361E-18 0"
        rpy="0 0 0" />
      <mass
        value="0.0432977871437822" />
      <inertia
        ixx="6.10360523604235E-06"
        ixy="-4.44323501180997E-22"
        ixz="-4.2351647362715E-22"
        iyy="1.24187338524514E-05"
        iyz="-8.90679628316095E-22"
        izz="1.27607093027641E-05" />
    </inertial>
    <visual>
      <origin
        xyz="0 0 0"
        rpy="0 0 0" />
      <geometry>
        <mesh
          filename="package://mutifingerhand_qi_urdf/meshes/L43.STL" />
      </geometry>
      <material
        name="">
        <color
          rgba="0.650980392156863 0.619607843137255 0.588235294117647 1" />
      </material>
    </visual>
    <collision>
      <origin
        xyz="0 0 0"
        rpy="0 0 0" />
      <geometry>
        <mesh
          filename="package://mutifingerhand_qi_urdf/meshes/L43.STL" />
      </geometry>
    </collision>
  </link>
  <joint
    name="J43"
    type="revolute">
    <origin
      xyz="0.05 0 0"
      rpy="1.5708 0 0" />
    <parent
      link="L42" />
    <child
      link="L43" />
    <axis
      xyz="0 0 1" />
      <limit
        lower="0"
        upper="1.5707963267949"
        effort="10"
        velocity="0.2" />
      <safety_controller
        k_velocity="0.2"
        k_position="3"
        soft_lower_limit = "0"
        soft_upper_limit = "1.5707963267949"/>
  </joint>
  <link
    name="L44">
    <inertial>
      <origin
        xyz="0.0294288024878977 -2.94902990916057E-17 2.77555756156289E-17"
        rpy="0 0 0" />
      <mass
        value="0.0306024106567815" />
      <inertia
        ixx="4.30360645164555E-06"
        ixy="1.42779239258754E-21"
        ixz="-8.470329472543E-22"
        iyy="6.12985569320617E-06"
        iyz="1.66266387506012E-22"
        izz="5.64979818294009E-06" />
    </inertial>
    <visual>
      <origin
        xyz="0 0 0"
        rpy="0 0 0" />
      <geometry>
        <mesh
          filename="package://mutifingerhand_qi_urdf/meshes/L44.STL" />
      </geometry>
      <material
        name="">
        <color
          rgba="1 1 1 1" />
      </material>
    </visual>
    <collision>
      <origin
        xyz="0 0 0"
        rpy="0 0 0" />
      <geometry>
        <mesh
          filename="package://mutifingerhand_qi_urdf/meshes/L44.STL" />
      </geometry>
    </collision>
  </link>
  <joint
    name="J44"
    type="revolute">
    <origin
      xyz="0.06 0 0"
      rpy="0 0 0" />
    <parent
      link="L43" />
    <child
      link="L44" />
    <axis
      xyz="0 0 1" />
      <limit
        lower="0"
        upper="1.5707963267949"
        effort="10"
        velocity="0.2" />
      <safety_controller
        k_velocity="0.2"
        k_position="3"
        soft_lower_limit = "0"
        soft_upper_limit = "1.5707963267949"/>
  </joint>
  <link
    name="L51">
    <inertial>
      <origin
        xyz="6.93889390390723E-18 -1.45464950643964E-07 -1.45464950654373E-07"
        rpy="0 0 0" />
      <mass
        value="0.00533032952331043" />
      <inertia
        ixx="3.90144153680475E-07"
        ixy="-1.02097316129488E-11"
        ixz="1.02097316129707E-11"
        iyy="4.31614139914133E-07"
        iyz="1.12790036754609E-16"
        izz="4.31614139914133E-07" />
    </inertial>
    <visual>
      <origin
        xyz="0 0 0"
        rpy="0 0 0" />
      <geometry>
        <mesh
          filename="package://mutifingerhand_qi_urdf/meshes/L51.STL" />
      </geometry>
      <material
        name="">
        <color
          rgba="0.647058823529412 0.619607843137255 0.588235294117647 1" />
      </material>
    </visual>
    <collision>
      <origin
        xyz="0 0 0"
        rpy="0 0 0" />
      <geometry>
        <mesh
          filename="package://mutifingerhand_qi_urdf/meshes/L51.STL" />
      </geometry>
    </collision>
  </link>
<!--  <link
    name="L51">
    <inertial>
      <origin
        xyz="0 0 0"
        rpy="0 0 0" />
      <mass
        value="0" />
      <inertia
        ixx="0"
        ixy="0"
        ixz="0"
        iyy="0"
        iyz="0"
        izz="0" />
    </inertial>
    <visual>
      <origin
        xyz="0 0 0"
        rpy="0 0 0" />
      <geometry>
        <mesh
          filename="package://mutifingerhand_qi_urdf/meshes/L51.STL" />
      </geometry>
      <material
        name="">
        <color
          rgba="1 1 1 1" />
      </material>
    </visual>
    <collision>
      <origin
        xyz="0 0 0"
        rpy="0 0 0" />
      <geometry>
        <mesh
          filename="package://mutifingerhand_qi_urdf/meshes/L51.STL" />
      </geometry>
    </collision>
  </link>-->
  <joint
    name="J51"
    type="revolute">
    <origin
      xyz="-0.0890101456738759 -0.154170094696265 0.0986397817749958"
      rpy="0 -0.872664625997164 -2.09439510239318" />
    <parent
      link="Plam" />
    <child
      link="L51" />
    <axis
      xyz="0 0 1" />
      <limit
        lower="0"
        upper="1.5707963267949"
        effort="10"
        velocity="0.2" />
      <safety_controller
        k_velocity="0.2"
        k_position="3"
        soft_lower_limit = "0"
        soft_upper_limit = "1.5707963267949"/>
  </joint>
  <link
    name="L52">
    <inertial>
      <origin
        xyz="0.0257389350848427 0 6.93889390390723E-18"
        rpy="0 0 0" />
      <mass
        value="0.021339303176374" />
      <inertia
        ixx="3.13943117425313E-06"
        ixy="1.37642853928824E-21"
        ixz="2.88220668810134E-22"
        iyy="3.24390776504185E-06"
        iyz="2.92652574265324E-22"
        izz="3.32835367884699E-06" />
    </inertial>
    <visual>
      <origin
        xyz="0 0 0"
        rpy="0 0 0" />
      <geometry>
        <mesh
          filename="package://mutifingerhand_qi_urdf/meshes/L52.STL" />
      </geometry>
      <material
        name="">
        <color
          rgba="1 1 1 1" />
      </material>
    </visual>
    <collision>
      <origin
        xyz="0 0 0"
        rpy="0 0 0" />
      <geometry>
        <mesh
          filename="package://mutifingerhand_qi_urdf/meshes/L52.STL" />
      </geometry>
    </collision>
  </link>
  <joint
    name="J52"
    type="revolute">
    <origin
      xyz="0 0 0"
      rpy="-1.5707963267949 0 0" />
    <parent
      link="L51" />
    <child
      link="L52" />
    <axis
      xyz="0 0 1" />
      <limit
        lower="-0.34906585039"
        upper="0.34906585039"
        effort="10"
        velocity="0.2" />
      <safety_controller
        k_velocity="0.2"
        k_position="3"
        soft_lower_limit = "-0.34906585039"
        soft_upper_limit = "0.34906585039"/>
  </joint>
  <link
    name="L53">
    <inertial>
      <origin
        xyz="0.03 5.20417042793042E-18 0"
        rpy="0 0 0" />
      <mass
        value="0.0432977871437822" />
      <inertia
        ixx="6.10360523604235E-06"
        ixy="4.11627739318146E-23"
        ixz="4.2351647362715E-22"
        iyy="1.24187338524514E-05"
        iyz="-5.84540236541777E-22"
        izz="1.27607093027641E-05" />
    </inertial>
    <visual>
      <origin
        xyz="0 0 0"
        rpy="0 0 0" />
      <geometry>
        <mesh
          filename="package://mutifingerhand_qi_urdf/meshes/L53.STL" />
      </geometry>
      <material
        name="">
        <color
          rgba="0.650980392156863 0.619607843137255 0.588235294117647 1" />
      </material>
    </visual>
    <collision>
      <origin
        xyz="0 0 0"
        rpy="0 0 0" />
      <geometry>
        <mesh
          filename="package://mutifingerhand_qi_urdf/meshes/L53.STL" />
      </geometry>
    </collision>
  </link>
  <joint
    name="J53"
    type="revolute">
    <origin
      xyz="0.05 0 0"
      rpy="1.5707963267949 0 0" />
    <parent
      link="L52" />
    <child
      link="L53" />
    <axis
      xyz="0 0 1" />
      <limit
        lower="0"
        upper="1.5707963267949"
        effort="10"
        velocity="0.2" />
      <safety_controller
        k_velocity="0.2"
        k_position="3"
        soft_lower_limit = "0"
        soft_upper_limit = "1.5707963267949"/>
  </joint>
  <link
    name="L54">
    <inertial>
      <origin
        xyz="0.0294288024878977 -3.12250225675825E-17 8.32667268468867E-17"
        rpy="0 0 0" />
      <mass
        value="0.0306024106567816" />
      <inertia
        ixx="4.30360645164555E-06"
        ixy="2.2352840634969E-21"
        ixz="-8.470329472543E-22"
        iyy="6.12985569320617E-06"
        iyz="7.0682953462273E-23"
        izz="5.6497981829401E-06" />
    </inertial>
    <visual>
      <origin
        xyz="0 0 0"
        rpy="0 0 0" />
      <geometry>
        <mesh
          filename="package://mutifingerhand_qi_urdf/meshes/L54.STL" />
      </geometry>
      <material
        name="">
        <color
          rgba="1 1 1 1" />
      </material>
    </visual>
    <collision>
      <origin
        xyz="0 0 0"
        rpy="0 0 0" />
      <geometry>
        <mesh
          filename="package://mutifingerhand_qi_urdf/meshes/L54.STL" />
      </geometry>
    </collision>
  </link>
  <joint
    name="J54"
    type="revolute">
    <origin
      xyz="0.06 0 0"
      rpy="0 0 0" />
    <parent
      link="L53" />
    <child
      link="L54" />
    <axis
      xyz="0 0 1" />
    <limit
      lower="0"
      upper="1.5707963267949"
      effort="10"
      velocity="0.2" />
    <safety_controller
      k_velocity="0.2"
      k_position="3"
      soft_lower_limit = "0"
      soft_upper_limit = "1.5707963267949"/>
  </joint>
</robot>
